Job started
Traceback (most recent call last):
  File "dist_sst.py", line 286, in <module>
Traceback (most recent call last):
  File "dist_sst.py", line 286, in <module>
Traceback (most recent call last):
  File "dist_sst.py", line 286, in <module>
    dist.init_process_group(backend="mpi")#, world_size=int(sys.argv[1]))
  File "/share/apps/pytorch/0.3.0_4/python2.7/lib/python2.7/site-packages/torch/distributed/__init__.py", line 49, in init_process_group
    dist.init_process_group(backend="mpi")#, world_size=int(sys.argv[1]))
  File "/share/apps/pytorch/0.3.0_4/python2.7/lib/python2.7/site-packages/torch/distributed/__init__.py", line 49, in init_process_group
    dist.init_process_group(backend="mpi")#, world_size=int(sys.argv[1]))
  File "/share/apps/pytorch/0.3.0_4/python2.7/lib/python2.7/site-packages/torch/distributed/__init__.py", line 49, in init_process_group
    group_name, rank)
    group_name, rank)
    group_name, rank)
RuntimeError: the MPI backend is not available; try to recompile the THD package with MPI support at /pytorch/torch/lib/THD/process_group/General.cpp:17
RuntimeError: the MPI backend is not available; try to recompile the THD package with MPI support at /pytorch/torch/lib/THD/process_group/General.cpp:17
RuntimeError: the MPI backend is not available; try to recompile the THD package with MPI support at /pytorch/torch/lib/THD/process_group/General.cpp:17
-------------------------------------------------------
Primary job  terminated normally, but 1 process returned
a non-zero exit code.. Per user-direction, the job has been aborted.
-------------------------------------------------------
--------------------------------------------------------------------------
mpiexec detected that one or more processes exited with non-zero status, thus causing
the job to be terminated. The first process to do so was:

  Process name: [[10105,1],0]
  Exit code:    1
--------------------------------------------------------------------------
Job completed
